2024-04-02 22:37:31,554 INFO    StreamThr :41900 [internal.py:wandb_internal():86] W&B internal server running at pid: 41900, started at: 2024-04-02 22:37:31.553218
2024-04-02 22:37:31,556 DEBUG   HandlerThread:41900 [handler.py:handle_request():146] handle_request: status
2024-04-02 22:37:31,559 INFO    WriterThread:41900 [datastore.py:open_for_write():87] open: /Users/kunkerdthaisong/ipu/intern/wandb/run-20240402_223731-cejm9blt/run-cejm9blt.wandb
2024-04-02 22:37:31,559 DEBUG   SenderThread:41900 [sender.py:send():382] send: header
2024-04-02 22:37:31,560 DEBUG   SenderThread:41900 [sender.py:send():382] send: run
2024-04-02 22:37:32,281 INFO    SenderThread:41900 [dir_watcher.py:__init__():211] watching files in: /Users/kunkerdthaisong/ipu/intern/wandb/run-20240402_223731-cejm9blt/files
2024-04-02 22:37:32,281 INFO    SenderThread:41900 [sender.py:_start_run_threads():1136] run started: cejm9blt with start time 1712072251.554834
2024-04-02 22:37:32,287 DEBUG   HandlerThread:41900 [handler.py:handle_request():146] handle_request: check_version
2024-04-02 22:37:32,287 DEBUG   SenderThread:41900 [sender.py:send_request():409] send_request: check_version
2024-04-02 22:37:33,350 DEBUG   HandlerThread:41900 [handler.py:handle_request():146] handle_request: run_start
2024-04-02 22:37:33,355 DEBUG   HandlerThread:41900 [system_info.py:__init__():27] System info init
2024-04-02 22:37:33,355 DEBUG   HandlerThread:41900 [system_info.py:__init__():42] System info init done
2024-04-02 22:37:33,355 INFO    HandlerThread:41900 [system_monitor.py:start():194] Starting system monitor
2024-04-02 22:37:33,355 INFO    SystemMonitor:41900 [system_monitor.py:_start():158] Starting system asset monitoring threads
2024-04-02 22:37:33,355 INFO    HandlerThread:41900 [system_monitor.py:probe():214] Collecting system info
2024-04-02 22:37:33,355 INFO    SystemMonitor:41900 [interfaces.py:start():190] Started cpu monitoring
2024-04-02 22:37:33,356 INFO    SystemMonitor:41900 [interfaces.py:start():190] Started disk monitoring
2024-04-02 22:37:33,356 DEBUG   HandlerThread:41900 [system_info.py:probe():151] Probing system
2024-04-02 22:37:33,357 INFO    SystemMonitor:41900 [interfaces.py:start():190] Started gpuapple monitoring
2024-04-02 22:37:33,359 INFO    SystemMonitor:41900 [interfaces.py:start():190] Started memory monitoring
2024-04-02 22:37:33,360 INFO    SystemMonitor:41900 [interfaces.py:start():190] Started network monitoring
2024-04-02 22:37:33,362 DEBUG   HandlerThread:41900 [gitlib.py:_init_repo():56] git repository is invalid
2024-04-02 22:37:33,362 DEBUG   HandlerThread:41900 [system_info.py:probe():199] Probing system done
2024-04-02 22:37:33,362 DEBUG   HandlerThread:41900 [system_monitor.py:probe():223] {'os': 'macOS-14.4.1-arm64-arm-64bit', 'python': '3.11.1', 'heartbeatAt': '2024-04-02T15:37:33.357453', 'startedAt': '2024-04-02T15:37:31.547044', 'docker': None, 'cuda': None, 'args': (), 'state': 'running', 'program': '/Users/kunkerdthaisong/ipu/intern/train.py', 'codePathLocal': 'train.py', 'codePath': 'train.py', 'host': 'kuns-MacBook-Air.local', 'username': 'kunkerdthaisong', 'executable': '/usr/local/bin/python3', 'cpu_count': 8, 'cpu_count_logical': 8, 'disk': {'/': {'total': 228.27386474609375, 'used': 9.540138244628906}}, 'gpuapple': {'type': 'arm', 'vendor': 'Apple'}, 'memory': {'total': 8.0}}
2024-04-02 22:37:33,362 INFO    HandlerThread:41900 [system_monitor.py:probe():224] Finished collecting system info
2024-04-02 22:37:33,362 INFO    HandlerThread:41900 [system_monitor.py:probe():227] Publishing system info
2024-04-02 22:37:33,363 INFO    HandlerThread:41900 [system_monitor.py:probe():229] Finished publishing system info
2024-04-02 22:37:33,365 DEBUG   SenderThread:41900 [sender.py:send():382] send: files
2024-04-02 22:37:33,365 INFO    SenderThread:41900 [sender.py:_save_file():1403] saving file wandb-metadata.json with policy now
2024-04-02 22:37:33,367 DEBUG   HandlerThread:41900 [handler.py:handle_request():146] handle_request: python_packages
2024-04-02 22:37:33,367 DEBUG   SenderThread:41900 [sender.py:send_request():409] send_request: python_packages
2024-04-02 22:37:33,368 DEBUG   HandlerThread:41900 [handler.py:handle_request():146] handle_request: stop_status
2024-04-02 22:37:33,368 DEBUG   SenderThread:41900 [sender.py:send_request():409] send_request: stop_status
2024-04-02 22:37:33,369 DEBUG   HandlerThread:41900 [handler.py:handle_request():146] handle_request: internal_messages
2024-04-02 22:37:33,736 DEBUG   SenderThread:41900 [sender.py:send():382] send: telemetry
2024-04-02 22:37:34,290 INFO    Thread-12 :41900 [dir_watcher.py:_on_file_created():271] file/dir created: /Users/kunkerdthaisong/ipu/intern/wandb/run-20240402_223731-cejm9blt/files/requirements.txt
2024-04-02 22:37:34,290 INFO    Thread-12 :41900 [dir_watcher.py:_on_file_created():271] file/dir created: /Users/kunkerdthaisong/ipu/intern/wandb/run-20240402_223731-cejm9blt/files/output.log
2024-04-02 22:37:34,290 INFO    Thread-12 :41900 [dir_watcher.py:_on_file_created():271] file/dir created: /Users/kunkerdthaisong/ipu/intern/wandb/run-20240402_223731-cejm9blt/files/wandb-metadata.json
2024-04-02 22:37:34,492 INFO    wandb-upload_0:41900 [upload_job.py:push():131] Uploaded file /var/folders/b_/lgrfxxx575sg8v5fpdzxfmtm0000gn/T/tmp3_2k2c12wandb/rey5ndkc-wandb-metadata.json
2024-04-02 22:37:36,300 INFO    Thread-12 :41900 [dir_watcher.py:_on_file_modified():288] file/dir modified: /Users/kunkerdthaisong/ipu/intern/wandb/run-20240402_223731-cejm9blt/files/output.log
2024-04-02 22:37:37,068 DEBUG   HandlerThread:41900 [handler.py:handle_request():146] handle_request: status_report
2024-04-02 22:37:38,306 INFO    Thread-12 :41900 [dir_watcher.py:_on_file_modified():288] file/dir modified: /Users/kunkerdthaisong/ipu/intern/wandb/run-20240402_223731-cejm9blt/files/output.log
2024-04-02 22:37:40,313 INFO    Thread-12 :41900 [dir_watcher.py:_on_file_modified():288] file/dir modified: /Users/kunkerdthaisong/ipu/intern/wandb/run-20240402_223731-cejm9blt/files/output.log
2024-04-02 22:37:42,178 DEBUG   HandlerThread:41900 [handler.py:handle_request():146] handle_request: status_report
2024-04-02 22:37:42,319 INFO    Thread-12 :41900 [dir_watcher.py:_on_file_modified():288] file/dir modified: /Users/kunkerdthaisong/ipu/intern/wandb/run-20240402_223731-cejm9blt/files/output.log
2024-04-02 22:37:44,330 INFO    Thread-12 :41900 [dir_watcher.py:_on_file_modified():288] file/dir modified: /Users/kunkerdthaisong/ipu/intern/wandb/run-20240402_223731-cejm9blt/files/output.log
2024-04-02 22:37:46,340 INFO    Thread-12 :41900 [dir_watcher.py:_on_file_modified():288] file/dir modified: /Users/kunkerdthaisong/ipu/intern/wandb/run-20240402_223731-cejm9blt/files/output.log
2024-04-02 22:37:47,588 DEBUG   HandlerThread:41900 [handler.py:handle_request():146] handle_request: status_report
2024-04-02 22:37:48,346 INFO    Thread-12 :41900 [dir_watcher.py:_on_file_modified():288] file/dir modified: /Users/kunkerdthaisong/ipu/intern/wandb/run-20240402_223731-cejm9blt/files/output.log
2024-04-02 22:37:48,372 DEBUG   HandlerThread:41900 [handler.py:handle_request():146] handle_request: stop_status
2024-04-02 22:37:48,372 DEBUG   SenderThread:41900 [sender.py:send_request():409] send_request: stop_status
2024-04-02 22:37:48,373 DEBUG   HandlerThread:41900 [handler.py:handle_request():146] handle_request: internal_messages
2024-04-02 22:37:50,357 INFO    Thread-12 :41900 [dir_watcher.py:_on_file_modified():288] file/dir modified: /Users/kunkerdthaisong/ipu/intern/wandb/run-20240402_223731-cejm9blt/files/output.log
2024-04-02 22:37:53,383 DEBUG   HandlerThread:41900 [handler.py:handle_request():146] handle_request: keepalive
2024-04-02 22:37:58,407 DEBUG   HandlerThread:41900 [handler.py:handle_request():146] handle_request: keepalive
2024-04-02 22:38:03,377 DEBUG   HandlerThread:41900 [handler.py:handle_request():146] handle_request: internal_messages
2024-04-02 22:38:08,448 DEBUG   HandlerThread:41900 [handler.py:handle_request():146] handle_request: keepalive
2024-04-02 22:38:09,575 INFO    SenderThread:41900 [retry.py:__call__():172] Retry attempt failed:
Traceback (most recent call last):
  File "/Library/Frameworks/Python.framework/Versions/3.11/lib/python3.11/site-packages/urllib3/connection.py", line 174, in _new_conn
    conn = connection.create_connection(
           ^^^^^^^^^^^^^^^^^^^^^^^^^^^^^
  File "/Library/Frameworks/Python.framework/Versions/3.11/lib/python3.11/site-packages/urllib3/util/connection.py", line 72, in create_connection
    for res in socket.getaddrinfo(host, port, family, socket.SOCK_STREAM):
               ^^^^^^^^^^^^^^^^^^^^^^^^^^^^^^^^^^^^^^^^^^^^^^^^^^^^^^^^^^
  File "/Library/Frameworks/Python.framework/Versions/3.11/lib/python3.11/socket.py", line 962, in getaddrinfo
    for res in _socket.getaddrinfo(host, port, family, type, proto, flags):
               ^^^^^^^^^^^^^^^^^^^^^^^^^^^^^^^^^^^^^^^^^^^^^^^^^^^^^^^^^^^
socket.gaierror: [Errno 8] nodename nor servname provided, or not known

During handling of the above exception, another exception occurred:

Traceback (most recent call last):
  File "/Library/Frameworks/Python.framework/Versions/3.11/lib/python3.11/site-packages/urllib3/connectionpool.py", line 703, in urlopen
    httplib_response = self._make_request(
                       ^^^^^^^^^^^^^^^^^^^
  File "/Library/Frameworks/Python.framework/Versions/3.11/lib/python3.11/site-packages/urllib3/connectionpool.py", line 386, in _make_request
    self._validate_conn(conn)
  File "/Library/Frameworks/Python.framework/Versions/3.11/lib/python3.11/site-packages/urllib3/connectionpool.py", line 1042, in _validate_conn
    conn.connect()
  File "/Library/Frameworks/Python.framework/Versions/3.11/lib/python3.11/site-packages/urllib3/connection.py", line 358, in connect
    self.sock = conn = self._new_conn()
                       ^^^^^^^^^^^^^^^^
  File "/Library/Frameworks/Python.framework/Versions/3.11/lib/python3.11/site-packages/urllib3/connection.py", line 186, in _new_conn
    raise NewConnectionError(
urllib3.exceptions.NewConnectionError: <urllib3.connection.HTTPSConnection object at 0x117769b10>: Failed to establish a new connection: [Errno 8] nodename nor servname provided, or not known

During handling of the above exception, another exception occurred:

Traceback (most recent call last):
  File "/Library/Frameworks/Python.framework/Versions/3.11/lib/python3.11/site-packages/requests/adapters.py", line 489, in send
    resp = conn.urlopen(
           ^^^^^^^^^^^^^
  File "/Library/Frameworks/Python.framework/Versions/3.11/lib/python3.11/site-packages/urllib3/connectionpool.py", line 787, in urlopen
    retries = retries.increment(
              ^^^^^^^^^^^^^^^^^^
  File "/Library/Frameworks/Python.framework/Versions/3.11/lib/python3.11/site-packages/urllib3/util/retry.py", line 592, in increment
    raise MaxRetryError(_pool, url, error or ResponseError(cause))
urllib3.exceptions.MaxRetryError: HTTPSConnectionPool(host='api.wandb.ai', port=443): Max retries exceeded with url: /graphql (Caused by NewConnectionError('<urllib3.connection.HTTPSConnection object at 0x117769b10>: Failed to establish a new connection: [Errno 8] nodename nor servname provided, or not known'))

During handling of the above exception, another exception occurred:

Traceback (most recent call last):
  File "/Library/Frameworks/Python.framework/Versions/3.11/lib/python3.11/site-packages/wandb/sdk/lib/retry.py", line 131, in __call__
    result = self._call_fn(*args, **kwargs)
             ^^^^^^^^^^^^^^^^^^^^^^^^^^^^^^
  File "/Library/Frameworks/Python.framework/Versions/3.11/lib/python3.11/site-packages/wandb/sdk/internal/internal_api.py", line 369, in execute
    return self.client.execute(*args, **kwargs)  # type: ignore
           ^^^^^^^^^^^^^^^^^^^^^^^^^^^^^^^^^^^^
  File "/Library/Frameworks/Python.framework/Versions/3.11/lib/python3.11/site-packages/wandb/vendor/gql-0.2.0/wandb_gql/client.py", line 52, in execute
    result = self._get_result(document, *args, **kwargs)
             ^^^^^^^^^^^^^^^^^^^^^^^^^^^^^^^^^^^^^^^^^^^
  File "/Library/Frameworks/Python.framework/Versions/3.11/lib/python3.11/site-packages/wandb/vendor/gql-0.2.0/wandb_gql/client.py", line 60, in _get_result
    return self.transport.execute(document, *args, **kwargs)
           ^^^^^^^^^^^^^^^^^^^^^^^^^^^^^^^^^^^^^^^^^^^^^^^^^
  File "/Library/Frameworks/Python.framework/Versions/3.11/lib/python3.11/site-packages/wandb/sdk/lib/gql_request.py", line 58, in execute
    request = self.session.post(self.url, **post_args)
              ^^^^^^^^^^^^^^^^^^^^^^^^^^^^^^^^^^^^^^^^
  File "/Library/Frameworks/Python.framework/Versions/3.11/lib/python3.11/site-packages/requests/sessions.py", line 635, in post
    return self.request("POST", url, data=data, json=json, **kwargs)
           ^^^^^^^^^^^^^^^^^^^^^^^^^^^^^^^^^^^^^^^^^^^^^^^^^^^^^^^^^
  File "/Library/Frameworks/Python.framework/Versions/3.11/lib/python3.11/site-packages/requests/sessions.py", line 587, in request
    resp = self.send(prep, **send_kwargs)
           ^^^^^^^^^^^^^^^^^^^^^^^^^^^^^^
  File "/Library/Frameworks/Python.framework/Versions/3.11/lib/python3.11/site-packages/requests/sessions.py", line 701, in send
    r = adapter.send(request, **kwargs)
        ^^^^^^^^^^^^^^^^^^^^^^^^^^^^^^^
  File "/Library/Frameworks/Python.framework/Versions/3.11/lib/python3.11/site-packages/requests/adapters.py", line 565, in send
    raise ConnectionError(e, request=request)
requests.exceptions.ConnectionError: HTTPSConnectionPool(host='api.wandb.ai', port=443): Max retries exceeded with url: /graphql (Caused by NewConnectionError('<urllib3.connection.HTTPSConnection object at 0x117769b10>: Failed to establish a new connection: [Errno 8] nodename nor servname provided, or not known'))
2024-04-02 22:38:13,464 DEBUG   HandlerThread:41900 [handler.py:handle_request():146] handle_request: keepalive
2024-04-02 22:38:18,382 DEBUG   HandlerThread:41900 [handler.py:handle_request():146] handle_request: internal_messages
2024-04-02 22:38:23,491 DEBUG   HandlerThread:41900 [handler.py:handle_request():146] handle_request: keepalive
2024-04-02 22:38:28,512 DEBUG   HandlerThread:41900 [handler.py:handle_request():146] handle_request: keepalive
2024-04-02 22:38:33,365 DEBUG   SystemMonitor:41900 [system_monitor.py:_start():172] Starting system metrics aggregation loop
2024-04-02 22:38:33,386 DEBUG   HandlerThread:41900 [handler.py:handle_request():146] handle_request: internal_messages
2024-04-02 22:38:36,338 DEBUG   HandlerThread:41900 [handler.py:handle_request():146] handle_request: poll_exit
2024-04-02 22:38:41,361 DEBUG   HandlerThread:41900 [handler.py:handle_request():146] handle_request: keepalive
2024-04-02 22:38:46,383 DEBUG   HandlerThread:41900 [handler.py:handle_request():146] handle_request: keepalive
2024-04-02 22:38:51,401 DEBUG   HandlerThread:41900 [handler.py:handle_request():146] handle_request: keepalive
2024-04-02 22:38:56,423 DEBUG   HandlerThread:41900 [handler.py:handle_request():146] handle_request: keepalive
2024-04-02 22:39:01,446 DEBUG   HandlerThread:41900 [handler.py:handle_request():146] handle_request: keepalive
2024-04-02 22:39:06,470 DEBUG   HandlerThread:41900 [handler.py:handle_request():146] handle_request: keepalive
2024-04-02 22:39:07,560 INFO    cpu       :41900 [interfaces.py:monitor():140] Process cpu has exited.
2024-04-02 22:39:07,562 INFO    memory    :41900 [interfaces.py:monitor():140] Process proc.memory.rssMB has exited.
2024-04-02 22:39:07,562 DEBUG   SystemMonitor:41900 [system_monitor.py:_start():179] Finished system metrics aggregation loop
2024-04-02 22:39:07,562 DEBUG   SystemMonitor:41900 [system_monitor.py:_start():183] Publishing last batch of metrics
2024-04-02 22:39:08,965 WARNING StreamThr :41900 [internal.py:is_dead():414] Internal process exiting, parent pid 41867 disappeared
2024-04-02 22:39:08,966 ERROR   StreamThr :41900 [internal.py:wandb_internal():152] Internal process shutdown.
2024-04-02 22:39:09,572 INFO    HandlerThread:41900 [handler.py:finish():869] shutting down handler
2024-04-02 22:39:09,572 INFO    WriterThread:41900 [datastore.py:close():296] close: /Users/kunkerdthaisong/ipu/intern/wandb/run-20240402_223731-cejm9blt/run-cejm9blt.wandb
2024-04-02 22:39:09,572 INFO    HandlerThread:41900 [system_monitor.py:finish():203] Stopping system monitor
2024-04-02 22:39:09,573 INFO    HandlerThread:41900 [interfaces.py:finish():202] Joined cpu monitor
2024-04-02 22:39:09,573 INFO    HandlerThread:41900 [interfaces.py:finish():202] Joined disk monitor
2024-04-02 22:39:09,573 INFO    HandlerThread:41900 [interfaces.py:finish():202] Joined gpuapple monitor
2024-04-02 22:39:09,573 INFO    HandlerThread:41900 [interfaces.py:finish():202] Joined memory monitor
2024-04-02 22:39:09,573 INFO    HandlerThread:41900 [interfaces.py:finish():202] Joined network monitor
2024-04-02 22:46:13,011 WARNING FileStreamThread:41900 [file_stream.py:request_with_retry():668] requests_with_retry encountered retryable exception: HTTPSConnectionPool(host='api.wandb.ai', port=443): Read timed out. (read timeout=180.0). func: functools.partial(<bound method Session.post of <requests.sessions.Session object at 0x10256cb90>>, timeout=180.0), args: ('https://api.wandb.ai/files/my_lab/YOLOv8/cejm9blt/file_stream',), kwargs: {'json': {'files': {'output.log': {'offset': 7, 'content': ['ERROR 2024-04-02T15:37:47.768192        1/10         0G     0.9556      3.401      1.147         50        320:   3%|▎         | 8/282 [00:11<06:12,  1.36s/it]\n']}}, 'dropped': 0}}
2024-04-02 22:46:15,429 WARNING FileStreamThread:41900 [file_stream.py:request_with_retry():668] requests_with_retry encountered retryable exception: HTTPSConnectionPool(host='api.wandb.ai', port=443): Max retries exceeded with url: /files/my_lab/YOLOv8/cejm9blt/file_stream (Caused by NewConnectionError('<urllib3.connection.HTTPSConnection object at 0x11776e3d0>: Failed to establish a new connection: [Errno 8] nodename nor servname provided, or not known')). func: functools.partial(<bound method Session.post of <requests.sessions.Session object at 0x10256cb90>>, timeout=180.0), args: ('https://api.wandb.ai/files/my_lab/YOLOv8/cejm9blt/file_stream',), kwargs: {'json': {'files': {'output.log': {'offset': 7, 'content': ['ERROR 2024-04-02T15:37:47.768192        1/10         0G     0.9556      3.401      1.147         50        320:   3%|▎         | 8/282 [00:11<06:12,  1.36s/it]\n']}}, 'dropped': 0}}
2024-04-02 22:46:20,434 WARNING FileStreamThread:41900 [file_stream.py:request_with_retry():668] requests_with_retry encountered retryable exception: HTTPSConnectionPool(host='api.wandb.ai', port=443): Max retries exceeded with url: /files/my_lab/YOLOv8/cejm9blt/file_stream (Caused by NewConnectionError('<urllib3.connection.HTTPSConnection object at 0x11777cfd0>: Failed to establish a new connection: [Errno 8] nodename nor servname provided, or not known')). func: functools.partial(<bound method Session.post of <requests.sessions.Session object at 0x10256cb90>>, timeout=180.0), args: ('https://api.wandb.ai/files/my_lab/YOLOv8/cejm9blt/file_stream',), kwargs: {'json': {'files': {'output.log': {'offset': 7, 'content': ['ERROR 2024-04-02T15:37:47.768192        1/10         0G     0.9556      3.401      1.147         50        320:   3%|▎         | 8/282 [00:11<06:12,  1.36s/it]\n']}}, 'dropped': 0}}
2024-04-02 22:46:29,670 WARNING FileStreamThread:41900 [file_stream.py:request_with_retry():668] requests_with_retry encountered retryable exception: HTTPSConnectionPool(host='api.wandb.ai', port=443): Max retries exceeded with url: /files/my_lab/YOLOv8/cejm9blt/file_stream (Caused by NewConnectionError('<urllib3.connection.HTTPSConnection object at 0x11776e910>: Failed to establish a new connection: [Errno 8] nodename nor servname provided, or not known')). func: functools.partial(<bound method Session.post of <requests.sessions.Session object at 0x10256cb90>>, timeout=180.0), args: ('https://api.wandb.ai/files/my_lab/YOLOv8/cejm9blt/file_stream',), kwargs: {'json': {'files': {'output.log': {'offset': 7, 'content': ['ERROR 2024-04-02T15:37:47.768192        1/10         0G     0.9556      3.401      1.147         50        320:   3%|▎         | 8/282 [00:11<06:12,  1.36s/it]\n']}}, 'dropped': 0}}
2024-04-02 22:46:46,544 WARNING FileStreamThread:41900 [file_stream.py:request_with_retry():668] requests_with_retry encountered retryable exception: HTTPSConnectionPool(host='api.wandb.ai', port=443): Max retries exceeded with url: /files/my_lab/YOLOv8/cejm9blt/file_stream (Caused by NewConnectionError('<urllib3.connection.HTTPSConnection object at 0x117771810>: Failed to establish a new connection: [Errno 8] nodename nor servname provided, or not known')). func: functools.partial(<bound method Session.post of <requests.sessions.Session object at 0x10256cb90>>, timeout=180.0), args: ('https://api.wandb.ai/files/my_lab/YOLOv8/cejm9blt/file_stream',), kwargs: {'json': {'files': {'output.log': {'offset': 7, 'content': ['ERROR 2024-04-02T15:37:47.768192        1/10         0G     0.9556      3.401      1.147         50        320:   3%|▎         | 8/282 [00:11<06:12,  1.36s/it]\n']}}, 'dropped': 0}}
2024-04-02 22:47:20,860 WARNING FileStreamThread:41900 [file_stream.py:request_with_retry():668] requests_with_retry encountered retryable exception: HTTPSConnectionPool(host='api.wandb.ai', port=443): Max retries exceeded with url: /files/my_lab/YOLOv8/cejm9blt/file_stream (Caused by NewConnectionError('<urllib3.connection.HTTPSConnection object at 0x117771810>: Failed to establish a new connection: [Errno 8] nodename nor servname provided, or not known')). func: functools.partial(<bound method Session.post of <requests.sessions.Session object at 0x10256cb90>>, timeout=180.0), args: ('https://api.wandb.ai/files/my_lab/YOLOv8/cejm9blt/file_stream',), kwargs: {'json': {'files': {'output.log': {'offset': 7, 'content': ['ERROR 2024-04-02T15:37:47.768192        1/10         0G     0.9556      3.401      1.147         50        320:   3%|▎         | 8/282 [00:11<06:12,  1.36s/it]\n']}}, 'dropped': 0}}
2024-04-02 22:48:28,609 WARNING FileStreamThread:41900 [file_stream.py:request_with_retry():668] requests_with_retry encountered retryable exception: HTTPSConnectionPool(host='api.wandb.ai', port=443): Max retries exceeded with url: /files/my_lab/YOLOv8/cejm9blt/file_stream (Caused by NewConnectionError('<urllib3.connection.HTTPSConnection object at 0x11776c910>: Failed to establish a new connection: [Errno 8] nodename nor servname provided, or not known')). func: functools.partial(<bound method Session.post of <requests.sessions.Session object at 0x10256cb90>>, timeout=180.0), args: ('https://api.wandb.ai/files/my_lab/YOLOv8/cejm9blt/file_stream',), kwargs: {'json': {'files': {'output.log': {'offset': 7, 'content': ['ERROR 2024-04-02T15:37:47.768192        1/10         0G     0.9556      3.401      1.147         50        320:   3%|▎         | 8/282 [00:11<06:12,  1.36s/it]\n']}}, 'dropped': 0}}
2024-04-02 22:53:13,863 INFO    SenderThread:41900 [sender.py:finish():1572] shutting down sender
2024-04-02 22:53:14,561 INFO    SenderThread:41900 [dir_watcher.py:finish():358] shutting down directory watcher
2024-04-02 22:53:15,184 INFO    SenderThread:41900 [dir_watcher.py:_on_file_modified():288] file/dir modified: /Users/kunkerdthaisong/ipu/intern/wandb/run-20240402_223731-cejm9blt/files/output.log
2024-04-02 22:53:15,185 INFO    SenderThread:41900 [dir_watcher.py:finish():388] scan: /Users/kunkerdthaisong/ipu/intern/wandb/run-20240402_223731-cejm9blt/files
2024-04-02 22:53:15,185 INFO    SenderThread:41900 [dir_watcher.py:finish():402] scan save: /Users/kunkerdthaisong/ipu/intern/wandb/run-20240402_223731-cejm9blt/files/requirements.txt requirements.txt
2024-04-02 22:53:15,186 INFO    SenderThread:41900 [dir_watcher.py:finish():402] scan save: /Users/kunkerdthaisong/ipu/intern/wandb/run-20240402_223731-cejm9blt/files/output.log output.log
2024-04-02 22:53:15,192 INFO    SenderThread:41900 [dir_watcher.py:finish():402] scan save: /Users/kunkerdthaisong/ipu/intern/wandb/run-20240402_223731-cejm9blt/files/config.yaml config.yaml
2024-04-02 22:53:15,193 INFO    SenderThread:41900 [dir_watcher.py:finish():402] scan save: /Users/kunkerdthaisong/ipu/intern/wandb/run-20240402_223731-cejm9blt/files/wandb-metadata.json wandb-metadata.json
2024-04-02 22:53:15,195 INFO    SenderThread:41900 [file_pusher.py:finish():172] shutting down file pusher
2024-04-02 22:53:15,196 INFO    SenderThread:41900 [file_pusher.py:join():178] waiting for file pusher
2024-04-02 22:53:16,117 INFO    wandb-upload_2:41900 [upload_job.py:push():131] Uploaded file /Users/kunkerdthaisong/ipu/intern/wandb/run-20240402_223731-cejm9blt/files/config.yaml
2024-04-02 22:53:33,422 ERROR   wandb-upload_0:41900 [internal_api.py:upload_file():2765] upload_file exception https://storage.googleapis.com/wandb-production.appspot.com/my_lab/YOLOv8/cejm9blt/requirements.txt?Expires=1712159595&GoogleAccessId=gorilla-files-url-signer-man%40wandb-production.iam.gserviceaccount.com&Signature=s0BqRX%2FOh2Q0iD%2BJNpEtIltuGOYTDRP4FQoDv87kgVPtgiumFioRoDkPYogGYC1nZj8gB0FHiCFutAiNb899GbFjcwHdMYgdAfA0dqbadYfJApLSiZUFWxpMpAhrJFLijjUJ7x8FgIenf8Wj12l0Td0XtjyX2qoqMc%2BDMgCQXzIFwdJPwAN6XlRLIAnAIQRyIuTDHaDBPXLLLA7mmwd%2BmH%2BKxLANj32ary31hU6ZVQzUj3bxMM15Xakz2vRGGSM449maeMlrahV5a0zlt%2B68g4tPmAtICBcyoUFKv58ieiZk96vjQkrySXPi%2FLB%2Bodse9cOXGgmWfBVCEQCZ2M4oyA%3D%3D: ('Connection aborted.', RemoteDisconnected('Remote end closed connection without response'))
2024-04-02 22:53:33,422 ERROR   wandb-upload_0:41900 [internal_api.py:upload_file():2767] upload_file request headers: {'User-Agent': 'python-requests/2.28.1', 'Accept-Encoding': 'gzip, deflate', 'Accept': '*/*', 'Connection': 'keep-alive', 'Content-Length': '2958'}
2024-04-02 22:53:33,422 ERROR   wandb-upload_0:41900 [internal_api.py:upload_file():2769] upload_file response body: 
2024-04-02 22:53:34,946 INFO    wandb-upload_0:41900 [upload_job.py:push():131] Uploaded file /Users/kunkerdthaisong/ipu/intern/wandb/run-20240402_223731-cejm9blt/files/requirements.txt
2024-04-02 22:53:35,300 INFO    wandb-upload_1:41900 [upload_job.py:push():131] Uploaded file /Users/kunkerdthaisong/ipu/intern/wandb/run-20240402_223731-cejm9blt/files/output.log
2024-04-02 22:53:35,871 INFO    SenderThread:41900 [file_stream.py:finish():595] file stream finish called
2024-04-02 22:53:36,185 INFO    SenderThread:41900 [file_stream.py:finish():599] file stream finish is done
